<?xml version="1.0"?>
<robot xmlns:xacro="http://ros.org/wiki/xacro" name="eve">
  
  <!--- Surface properties must come first? -->
  <gazebo reference="front_left_wheel">
    <mu1>0.9</mu1>
    <mu2>0.9</mu2>
    <minDepth>0.005</minDepth>
    <kp>1e8</kp>
  </gazebo>
  
  <gazebo reference="front_right_wheel">
    <mu1>0.9</mu1>
    <mu2>0.9</mu2>
    <minDepth>0.005</minDepth>
    <kp>1e8</kp>
  </gazebo>
  
  <gazebo reference="rear_left_wheel">
    <mu1>0.9</mu1>
    <mu2>0.9</mu2>
    <minDepth>0.005</minDepth>
    <kp>1e8</kp>
  </gazebo>
  
  <gazebo reference="rear_right_wheel">
    <mu1>0.9</mu1>
    <mu2>0.9</mu2>
    <minDepth>0.005</minDepth>
    <kp>1e8</kp>
  </gazebo>

  <!--- Eve Body -->
  <link name="base_link">
    <inertial>
      <mass value="1"/>
      <inertia ixx="0.001" ixy="0.0" ixz="0.0" iyy="0.001" iyz="0.0" izz="0.001"/>
    </inertial>
  </link>

  <link name="chassis">
    <visual>
      <origin xyz="0 0 0" rpy="0 0 0"/>
      <geometry>
        <mesh filename="package://eve_description/meshes/eve_body.stl"/>
      </geometry>
    </visual>
    <collision name="chassis">
      <origin xyz="0 0 0" rpy="0 0 0"/>
      <geometry>
        <mesh filename="package://eve_description/meshes/eve_body.stl"/>
      </geometry>
    </collision>
    <inertial>
      <mass value="1100.0"/>
      <origin xyz="0.528 0 0.421" rpy="0 0 0"/>
      <inertia ixx="430.1" ixy="0.0" ixz="-88.55" iyy="1382.0" iyz="0.0" izz="1422"/>
    </inertial>
  </link>

  <joint name="base_link_connection" type="fixed">
    <parent link="base_link"/>
    <child link="chassis"/>
    <origin xyz="0 0 0" rpy="0 0 0"/>
    <axis xyz="0 0 0"/>
  </joint>

  <link name="fl_axle">
    <inertial>
      <mass value="1"/>
      <origin xyz="0 0 0"/>
      <inertia ixx="0.004" ixy="0.0" ixz="0.0" iyy="0.004" iyz="0.0" izz="0.004"/>
    </inertial>
  </link>

  <link name="fr_axle">
    <inertial>
      <mass value="1"/>
      <origin xyz="0 0 0"/>
      <inertia ixx="0.004" ixy="0.0" ixz="0.0" iyy="0.004" iyz="0.0" izz="0.004"/>
    </inertial>
  </link>
  
  <link name="front_left_wheel">
    <inertial>
      <mass value="25"/>
      <origin xyz="0 0 0"/>
      <inertia ixx="0.6222" ixy="-0.00001993" ixz="-0.00001035" iyy="1.095" iyz="0.0" izz="0.6222"/>
    </inertial>
    <collision name="front_left_wheel_collision">
      <origin xyz="0 0 0" rpy="1.5708 0 0"/>
      <geometry>
        <cylinder radius="0.28" length="0.165"/>
      </geometry>
    </collision>
    <visual>
      <origin xyz="0 0 0" rpy="0 0 0"/>
      <geometry>
        <mesh filename="package://eve_description/meshes/wheel.stl"/>
      </geometry>
    </visual>
  </link>

  <link name="front_right_wheel">
    <inertial>
      <mass value="25"/>
      <origin xyz="0 0 0"/>
      <inertia ixx="0.6222" ixy="-0.00001993" ixz="-0.00001035" iyy="1.095" iyz="0.0" izz="0.6222"/>
    </inertial>
    <collision name="front_right_wheel_collision">
      <origin xyz="0 0 0" rpy="1.5708 0 0"/>
      <geometry>
        <cylinder radius="0.28" length="0.165"/>
      </geometry>
    </collision>
    <visual>
      <origin xyz="0 0 0" rpy="3.14159 0 0"/>
      <geometry>
        <mesh filename="package://eve_description/meshes/wheel.stl"/>
      </geometry>
    </visual>
  </link>

  <link name="rear_left_wheel">
    <inertial>
      <mass value="25"/>
      <origin xyz="0 0 0"/>
      <inertia ixx="0.6222" ixy="-0.00001993" ixz="-0.00001035" iyy="1.095" iyz="0.0" izz="0.6222"/>
    </inertial>
    <collision name="rear_left_wheel_collision">
      <origin xyz="0 0 0" rpy="1.5708 0 0"/>
      <geometry>
        <cylinder radius="0.28" length="0.165"/>
      </geometry>
    </collision>
    <visual>
      <origin xyz="0 0 0" rpy="0 0 0"/>
      <geometry>
        <mesh filename="package://eve_description/meshes/wheel.stl"/>
      </geometry>
    </visual>
  </link>

  <link name="rear_right_wheel">
    <inertial>
      <mass value="25"/>
      <origin xyz="0 0 0"/>
      <inertia ixx="0.6222" ixy="-0.00001993" ixz="-0.00001035" iyy="1.095" iyz="0.0" izz="0.6222"/>
    </inertial>
    <collision name="rear_right_wheel_collision">
      <origin xyz="0 0 0" rpy="1.5708 0 0"/>
      <geometry>
        <cylinder radius="0.28" length="0.165"/>
      </geometry>
    </collision>
    <visual>
      <origin xyz="0 0 0" rpy="3.14159 0 0"/>
      <geometry>
        <mesh filename="package://eve_description/meshes/wheel.stl"/>
      </geometry>
    </visual>
  </link>

  <link name="steering_wheel">
    <inertial>
      <mass value="1.0"/>
      <inertia ixx="0.001" ixy="0.0" ixz="0.0" iyy="0.001" iyz="0.0" izz="0.001"/>
    </inertial>
    <visual>
      <origin xyz="0 0 0" rpy="0 1.302101 0"/>
      <geometry>
        <cylinder radius="0.1" length="0.01"/>
      </geometry>
    </visual>
  </link>

  <joint name="steering_joint" type="continuous">
    <origin xyz="1.44 -0.26 0.756" rpy="0 0 0"/>
    <parent link="chassis"/>
    <child link="steering_wheel"/>
    <axis xyz="0 0 1"/>
    <limit lower="-7.85" upper="7.85" effort="10000000" velocity="1000000"/>
  </joint>

  <joint name="front_left_steer_joint" type="continuous">
    <parent link="chassis"/>
    <child link="fl_axle"/>
    <origin xyz="1.958 0.665 0" rpy="0 0 0"/>
    <axis xyz="0 0 1"/>
    <limit lower="-0.8727" upper="0.8727" effort="10000000" velocity="1000000"/>
  </joint>

  <joint name="front_right_steer_joint" type="continuous">
    <parent link="chassis"/>
    <child link="fr_axle"/>
    <origin xyz="1.958 -0.665 0" rpy="0 0 0"/>
    <axis xyz="0 0 1"/>
    <limit lower="-0.8727" upper="0.8727" effort="10000000" velocity="1000000"/>
  </joint>

  <joint name="front_left_wheel_joint" type="continuous">
    <parent link="fl_axle"/>
    <child link="front_left_wheel"/>
    <origin xyz="0 0 0" rpy="0 0 0"/>
    <axis xyz="0 1 0"/>
  </joint>

  <joint name="front_right_wheel_joint" type="continuous">
    <parent link="fr_axle"/>
    <child link="front_right_wheel"/>
    <origin xyz="0 0 0" rpy="0 0 0"/>
    <axis xyz="0 1 0"/>
  </joint>

  <joint name="rear_left_wheel_joint" type="continuous">
    <parent link="chassis"/>
    <child link="rear_left_wheel"/>
    <origin xyz="0 0.665 0" rpy="0 0 0"/>
    <axis xyz="0 1 0"/>
  </joint>
  
  <joint name="rear_right_wheel_joint" type="continuous">
    <parent link="chassis"/>
    <child link="rear_right_wheel"/>
    <origin xyz="0 -0.665 0" rpy="0 0 0"/>
    <axis xyz="0 1 0"/>
  </joint>

  <!--- Sensors -->

  <!--- 3D Lidar -->

  <link name="top_laser_link">
    <inertial>
      <mass value="1"/>
      <inertia ixx="0.001" ixy="0.0" ixz="0.0" iyy="0.001" iyz="0.0" izz="0.001"/>
    </inertial>
    <visual>
      <origin xyz="0 0 -0.06" rpy="0 0 0"/>
      <geometry>
        <mesh filename="package://eve_description/meshes/3DLidar.stl"/>
      </geometry>
    </visual>
    <collision name="top_laser_collision">
      <origin xyz="0 0 -0.0165" rpy="0 0 0"/>
      <geometry>
        <cylinder radius="0.048" length="0.087"/>
      </geometry>
    </collision>
  </link>

  <joint name="top_laser_joint" type="fixed">
    <parent link="chassis"/>
    <child link="top_laser_link"/>
    <origin xyz="0.528 0 1.658" rpy="0 0 0"/>
  </joint>

  <!--- 2D Lidars -->

  <link name="front_center_laser_link">
    <inertial>
      <mass value="1"/>
      <inertia ixx="0.001" ixy="0.0" ixz="0.0" iyy="0.001" iyz="0.0" izz="0.001"/>
    </inertial>
    <visual>
      <origin xyz="0 0 0" rpy="0 0 0"/>
      <geometry>
        <mesh filename="package://eve_description/meshes/2DLidar.stl"/>
      </geometry>
    </visual>
    <collision name="front_center_laser_collision">
      <origin xyz="0 0 -0.04" rpy="0 0 0"/>
      <geometry>
        <cylinder radius="0.049" length="0.150"/>
      </geometry>
    </collision>
  </link>

  <joint name="front_center_laser_joint" type="fixed">
    <parent link="chassis"/>
    <child link="front_center_laser_link"/>
    <origin xyz="2.71 0 0.421" rpy="0 0 0"/>
  </joint>

  <link name="back_left_laser_link">
    <inertial>
      <mass value="1"/>
      <inertia ixx="0.001" ixy="0.0" ixz="0.0" iyy="0.001" iyz="0.0" izz="0.001"/>
    </inertial>
    <visual>
      <origin xyz="0 0 0" rpy="0 0 0"/>
      <geometry>
        <mesh filename="package://eve_description/meshes/2DLidar.stl"/>
      </geometry>
    </visual>
    <collision name="back_left_laser_collision">
      <origin xyz="0 0 -0.04" rpy="0 0 0"/>
      <geometry>
        <cylinder radius="0.049" length="0.150"/>
      </geometry>
    </collision>
  </link>

  <joint name="back_left_laser_joint" type="fixed">
    <parent link="chassis"/>
    <child link="back_left_laser_link"/>
    <origin xyz="-0.876 0.820 0.291" rpy="0 0 2.356"/>
  </joint>

  <link name="back_right_laser_link">
    <inertial>
      <mass value="1"/>
      <inertia ixx="0.001" ixy="0.0" ixz="0.0" iyy="0.001" iyz="0.0" izz="0.001"/>
    </inertial>
    <visual>
      <origin xyz="0 0 0" rpy="0 0 0"/>
      <geometry>
        <mesh filename="package://eve_description/meshes/2DLidar.stl"/>
      </geometry>
    </visual>
    <collision name="back_right_laser_collision">
      <origin xyz="0 0 -0.04" rpy="0 0 0"/>
      <geometry>
        <cylinder radius="0.049" length="0.150"/>
      </geometry>
    </collision>
  </link>

  <joint name="back_right_laser_joint" type="fixed">
    <parent link="chassis"/>
    <child link="back_right_laser_link"/>
    <origin xyz="-0.876 -0.820 0.291" rpy="0 0 -2.356"/>
  </joint>

  <!--- ZED -->

  <link name="zed_camera_center">
    <inertial>
      <mass value="0.1"/>
      <inertia ixx="0.0001" ixy="0.0" ixz="0.0" iyy="0.0001" iyz="0.0" izz="0.0001"/>
    </inertial>
    <visual>
      <origin xyz="0 0 0" rpy="0 0 0"/>
      <geometry>
        <mesh filename="package://eve_description/meshes/zed.stl"/>
      </geometry>
    </visual>
    <collision name="back_right_laser_collision">
      <geometry>
        <box size="0.033 0.175 0.033"/>1
      </geometry>
    </collision>
  </link>

  <link name="zed_left_camera_frame" />
  
  <link name="zed_left_camera_optical_frame"/>
  
  <joint name="zed_left_camera_joint" type="fixed">
    <parent link="zed_camera_center"/>
    <child link="zed_left_camera_frame"/>
    <origin xyz="0 0.06 0" rpy="0 0 0" />
  </joint>

  <joint name="zed_left_camera_optical_joint" type="fixed">
    <origin xyz="0 0 0" rpy="0 0.0 0"/>
    <parent link="zed_left_camera_frame"/>
    <child link="zed_left_camera_optical_frame"/>
  </joint>

  <link name="zed_right_camera_frame" />
  
  <link name="zed_right_camera_optical_frame"/>

  <joint name="zed_right_camera_joint" type="fixed">
    <parent link="zed_camera_center"/>
    <child link="zed_right_camera_frame"/>
    <origin xyz="0 -0.06 0" rpy="0 0 0" />
  </joint>

  <joint name="zed_right_camera_optical_joint" type="fixed">
    <origin xyz="0 0 0" rpy="0 0.0 0"/>
    <parent link="zed_right_camera_frame"/>
    <child link="zed_right_camera_optical_frame"/>
  </joint>

  <joint name="chassis_zed_joint" type="fixed">
    <parent link="chassis"/>
    <child link="zed_camera_center"/>
    <origin xyz="2.072 0 0.737" rpy="0 0 0"/>
  </joint>

  <gazebo>
    <plugin name="eve_drive" filename="libEvePlugin.so">
      <base_link>base_link</base_link>
      <front_left_wheel>front_left_wheel_joint</front_left_wheel>
      <front_right_wheel>front_right_wheel_joint</front_right_wheel>
      <front_left_wheel_steering>front_left_steer_joint</front_left_wheel_steering>
      <front_right_wheel_steering>front_right_steer_joint</front_right_wheel_steering>
      <back_left_wheel>rear_left_wheel_joint</back_left_wheel>
      <back_right_wheel>rear_right_wheel_joint</back_right_wheel>
      <steering_wheel>steering_joint</steering_wheel>
      <autonomous_mode>false</autonomous_mode>
      <convert_ang_vel_to_steer>false</convert_ang_vel_to_steer>
      <cmd_topic>/eve_drive</cmd_topic>
      <odom_topic>/odom</odom_topic>
      <odom_frame>odom</odom_frame>
      <odom_rate>50</odom_rate>
      <front_torque>859.4004393000001</front_torque>
      <back_torque>0</back_torque>
      <front_brake_torque>1031.28052716</front_brake_torque>
      <back_brake_torque>687.5203514400001</back_brake_torque>
      <max_speed>22.5</max_speed>
      <max_steer>0.6458</max_steer>
      <flwheel_steering_p_gain>1e4</flwheel_steering_p_gain>
      <frwheel_steering_p_gain>1e4</frwheel_steering_p_gain>
      <flwheel_steering_i_gain>0</flwheel_steering_i_gain>
      <frwheel_steering_i_gain>0</frwheel_steering_i_gain>
      <flwheel_steering_d_gain>3e2</flwheel_steering_d_gain>
      <frwheel_steering_d_gain>3e2</frwheel_steering_d_gain>
      <linear_velocity_p_gain>2000.0</linear_velocity_p_gain>
      <linear_velocity_i_gain>1000.0</linear_velocity_i_gain>
      <linear_velocity_d_gain>0.0</linear_velocity_d_gain>
      <linear_velocity_i_max>500.0</linear_velocity_i_max>
      <linear_velocity_i_min>-500.0</linear_velocity_i_min>
      <angular_velocity_p_gain>0.1</angular_velocity_p_gain>
      <angular_velocity_i_gain>0.01</angular_velocity_i_gain>
      <angular_velocity_d_gain>0.0</angular_velocity_d_gain>
      <angular_velocity_i_max>0.1</angular_velocity_i_max>
      <angular_velocity_i_min>-0.1</angular_velocity_i_min>
      <wheel_joint_damping_coefficient>7.5</wheel_joint_damping_coefficient>
    </plugin>
  </gazebo>

  <gazebo>
    <plugin name="joint_state_publisher" filename="libgazebo_ros_joint_state_publisher.so">
      <jointName>rear_right_wheel_joint, rear_left_wheel_joint, front_right_wheel_joint, front_left_wheel_joint, front_right_steer_joint, front_left_steer_joint, steering_joint</jointName>
      <updateRate>100.0</updateRate>
      <alwaysOn>true</alwaysOn>
    </plugin>
  </gazebo>

  <gazebo reference="top_laser_link">
    <sensor name="top_laser_sensor" type="ray">
      <update_rate>10</update_rate>
      <visualize>false</visualize>
      <ray>
        <scan>
          <horizontal>
            <samples>1000</samples>
            <resolution>1</resolution>
            <min_angle>-3.14159</min_angle>
            <max_angle>3.14159</max_angle>
          </horizontal>
          <vertical>
            <samples>8</samples>
            <resolution>1</resolution>
            <min_angle>-0.318505</min_angle>
            <max_angle>0.0557982</max_angle>
          </vertical>
        </scan>
        <range>
          <min>0.055</min>
          <max>150</max>
          <resolution>0.001</resolution>
        </range>
        <noise>
          <type>gaussian</type>
          <mean>0</mean>
          <stddev>0</stddev>
        </noise>
      </ray>
      <plugin name="top_laser" filename="package://eve_description/plugins/libgazebo_ros_3d_lidar.so">
        <topicName>/eve/top_laser/scan</topicName>
        <frameName>top_laser_link</frameName>
        <min_range>0.9</min_range>
        <max_range>130.0</max_range>
        <gaussianNoise>0.008</gaussianNoise>
      </plugin>
    </sensor>
  </gazebo>

  <gazebo reference="front_center_laser_link">
    <sensor name='front_center_laser_sensor' type='ray'>
      <visualize>false</visualize>
      <ray>
        <scan>
          <horizontal>
            <samples>640</samples>
            <resolution>1</resolution>
            <min_angle>-2.26889</min_angle>
            <max_angle>2.2689</max_angle>
          </horizontal>
          <vertical>
            <samples>1</samples>
            <min_angle>0</min_angle>
            <max_angle>0</max_angle>
          </vertical>
        </scan>
        <range>
          <min>0.2</min>
          <max>30</max>
          <resolution>0.01</resolution>
        </range>
      </ray>
      <plugin name='front_center_laser' filename='libgazebo_ros_laser.so'>
        <topicName>/eve/front_center_laser/scan</topicName>
        <frameName>front_center_laser_link</frameName>
      </plugin>
      <always_on>1</always_on>
      <update_rate>30</update_rate>
      <visualize>0</visualize>
    </sensor>
  </gazebo>

  <gazebo reference="back_left_laser_link">
    <sensor name='back_left_laser_sensor' type='ray'>
      <visualize>false</visualize>
      <ray>
        <scan>
          <horizontal>
            <samples>640</samples>
            <resolution>1</resolution>
            <min_angle>-2.26889</min_angle>
            <max_angle>2.2689</max_angle>
          </horizontal>
          <vertical>
            <samples>1</samples>
            <min_angle>0</min_angle>
            <max_angle>0</max_angle>
          </vertical>
        </scan>
        <range>
          <min>0.2</min>
          <max>30</max>
          <resolution>0.01</resolution>
        </range>
      </ray>
      <plugin name='back_left_laser' filename='libgazebo_ros_laser.so'>
        <topicName>/eve/back_left_laser/scan</topicName>
        <frameName>back_left_laser_link</frameName>
      </plugin>
      <always_on>1</always_on>
      <update_rate>30</update_rate>
      <visualize>0</visualize>
    </sensor>
  </gazebo>

  <gazebo reference="back_right_laser_link">
    <sensor name='back_right_laser_sensor' type='ray'>
      <visualize>false</visualize>
      <ray>
        <scan>
          <horizontal>
            <samples>640</samples>
            <resolution>1</resolution>
            <min_angle>-2.26889</min_angle>
            <max_angle>2.2689</max_angle>
          </horizontal>
          <vertical>
            <samples>1</samples>
            <min_angle>0</min_angle>
            <max_angle>0</max_angle>
          </vertical>
        </scan>
        <range>
          <min>0.2</min>
          <max>30</max>
          <resolution>0.01</resolution>
        </range>
      </ray>
      <plugin name='back_right_laser' filename='libgazebo_ros_laser.so'>
        <topicName>eve/back_right_laser/scan</topicName>
        <frameName>back_right_laser_link</frameName>
      </plugin>
      <always_on>1</always_on>
      <update_rate>30</update_rate>
      <visualize>0</visualize>
    </sensor>
  </gazebo>

   <gazebo reference="zed_camera_center">
    <sensor type="multicamera" name="zed">
      <update_rate>30</update_rate>
      <camera name="left">
        <pose>0 0.06 0 0 0 0</pose>
        <horizontal_fov>1.48353</horizontal_fov>
        <image>
          <width>1280</width>
          <height>720</height>
          <format>R8G8B8</format>
        </image>
        <clip>
          <near>0.5</near>
          <far>15.0</far>
        </clip>
        <noise>
          <type>gaussian</type>
          <mean>0.0</mean>
          <stddev>0.007</stddev>
        </noise>
      </camera>
      <camera name="right">
        <pose>0 -0.06 0 0 0 0</pose>
        <horizontal_fov>1.48353</horizontal_fov>
        <image>
          <width>1280</width>
          <height>720</height>
          <format>R8G8B8</format>
        </image>
        <clip>
          <near>0.5</near>
          <far>15.0</far>
        </clip>
        <noise>
          <type>gaussian</type>
          <mean>0.0</mean>
          <stddev>0.007</stddev>
        </noise>
      </camera>
      <plugin name="stereo_camera_controller" filename="libgazebo_ros_multicamera.so">
        <alwaysOn>true</alwaysOn>
        <updateRate>0.0</updateRate>
        <cameraName>zed</cameraName>
        <imageTopicName>image_raw</imageTopicName>
        <cameraInfoTopicName>camera_info</cameraInfoTopicName>
        <frameName>zed_left_camera_optical_frame</frameName>
        <!--<rightFrameName>right_camera_optical_frame</rightFrameName>-->
        <hackBaseline>0.07</hackBaseline>
        <distortionK1>0.0</distortionK1>
        <distortionK2>0.0</distortionK2>
        <distortionK3>0.0</distortionK3>
        <distortionT1>0.0</distortionT1>
        <distortionT2>0.0</distortionT2>
      </plugin>
    </sensor>
  </gazebo>
  
</robot>
